{
  "comments": [
    {
      "unresolved": false,
      "key": {
        "uuid": "6c5b99a5_c52be161",
        "filename": "/PATCHSET_LEVEL",
        "patchSetId": 1
      },
      "lineNbr": 0,
      "author": {
        "id": 4146
      },
      "writtenOn": "2023-02-09T21:38:35Z",
      "side": 1,
      "message": "recheck are these failures persistent?",
      "revId": "ee3339c8e6d76562983ca0da117234eac434671e",
      "serverId": "4a232e18-c5a9-48ee-94c0-e04e7cca6543"
    },
    {
      "unresolved": false,
      "key": {
        "uuid": "b8f5fad1_072531a9",
        "filename": "/PATCHSET_LEVEL",
        "patchSetId": 1
      },
      "lineNbr": 0,
      "author": {
        "id": 4146
      },
      "writtenOn": "2023-02-13T18:12:41Z",
      "side": 1,
      "message": "recheck pipeline locking in tests was fixed",
      "revId": "ee3339c8e6d76562983ca0da117234eac434671e",
      "serverId": "4a232e18-c5a9-48ee-94c0-e04e7cca6543"
    },
    {
      "unresolved": false,
      "key": {
        "uuid": "e179f054_665835e2",
        "filename": "/PATCHSET_LEVEL",
        "patchSetId": 1
      },
      "lineNbr": 0,
      "author": {
        "id": 4146
      },
      "writtenOn": "2023-02-13T23:26:53Z",
      "side": 1,
      "message": "recheck all of the tests were in the test_v3 file which this change does not modify. Looking closer it appears that we lost connectivity to mysql for some reason.",
      "revId": "ee3339c8e6d76562983ca0da117234eac434671e",
      "serverId": "4a232e18-c5a9-48ee-94c0-e04e7cca6543"
    }
  ]
}